Workbook

Sheet salesmonthly
A1: datum | B1: M01AB | C1: M01AE | D1: N02BA | E1: N02BE | F1: N05B | G1: N05C | H1: R03 | I1: R06 | J1: Year | K1: Month
A2: 41670 | B2: 127.69000000000001 | C2: 99.09000000000005 | D2: 152.09999999999997 | E2: 878.0300000000002 | F2: 354 | G2: 50 | H2: 112 | I2: 48.2 | J2: =YEAR(A2) -> 2014 | K2: =MONTH(A2) -> 1
A3: 41698 | B3: 133.32 | C3: 126.0500000000001 | D3: 176.99999999999997 | E3: 1001.9000000000001 | F3: 347 | G3: 31 | H3: 122 | I3: 36.2 | J3: =YEAR(A3) -> 2014 | K3: =MONTH(A3) -> 2
A4: 41729 | B4: 137.44000000000005 | C4: 92.95000000000007 | D4: 147.655 | E4: 779.275 | F4: 232 | G4: 20 | H4: 112 | I4: 85.4 | J4: =YEAR(A4) -> 2014 | K4: =MONTH(A4) -> 3
A5: 41759 | B5: 113.10000000000004 | C5: 89.47500000000008 | D5: 130.89999999999998 | E5: 698.5 | F5: 209 | G5: 18 | H5: 97 | I5: 73.7 | J5: =YEAR(A5) -> 2014 | K5: =MONTH(A5) -> 4
A6: 41790 | B6: 101.79000000000005 | C6: 119.93300000000009 | D6: 132.1 | E6: 628.7800000000001 | F6: 270 | G6: 23 | H6: 107 | I6: 123.69999999999999 | J6: =YEAR(A6) -> 2014 | K6: =MONTH(A6) -> 5
A7: 41820 | B7: 112.07000000000002 | C7: 94.71000000000006 | D7: 122.9 | E7: 548.225 | F7: 323 | G7: 23 | H7: 57 | I7: 109.3 | J7: =YEAR(A7) -> 2014 | K7: =MONTH(A7) -> 6
A8: 41851 | B8: 117.06000000000002 | C8: 95.01000000000012 | D8: 129.3 | E8: 491.9 | F8: 348 | G8: 21 | H8: 61 | I8: 69.1 | J8: =YEAR(A8) -> 2014 | K8: =MONTH(A8) -> 7
A9: 41882 | B9: 134.79000000000005 | C9: 99.78 | D9: 123.8 | E9: 583.8499999999999 | F9: 420 | G9: 29 | H9: 37 | I9: 70.80000000000001 | J9: =YEAR(A9) -> 2014 | K9: =MONTH(A9) -> 8
A10: 41912 | B10: 108.78000000000003 | C10: 109.0940000000001 | D10: 122.09999999999998 | E10: 887.8199999999999 | F10: 399 | G10: 14 | H10: 115 | I10: 58.8 | J10: =YEAR(A10) -> 2014 | K10: =MONTH(A10) -> 9
A11: 41943 | B11: 154.75000000000003 | C11: 185.2410000000001 | D11: 191.59999999999997 | E11: 1856.8149999999994 | F11: 472 | G11: 30 | H11: 182 | I11: 74.5 | J11: =YEAR(A11) -> 2014 | K11: =MONTH(A11) -> 10
A12: 41973 | B12: 138.08000000000004 | C12: 100.86000000000004 | D12: 142.7 | E12: 723.8 | F12: 489 | G12: 19 | H12: 112 | I12: 45.2 | J12: =YEAR(A12) -> 2014 | K12: =MONTH(A12) -> 11
A13: 42004 | B13: 131.90000000000003 | C13: 121.40100000000004 | D13: 111.12400000000001 | E13: 1015.6600000000001 | F13: 492 | G13: 25 | H13: 163 | I13: 33.4 | J13: =YEAR(A13) -> 2014 | K13: =MONTH(A13) -> 12
A14: 42035 | B14: 135.91000000000003 | C14: 130.34900000000005 | D14: 141 | E14: 1044.2400000000002 | F14: 463 | G14: 24 | H14: 177.25 | I14: 42 | J14: =YEAR(A14) -> 2015 | K14: =MONTH(A14) -> 1
A15: 42063 | B15: 115.71 | C15: 123.73999999999997 | D15: 131.83 | E15: 953.252 | F15: 243 | G15: 9 | H15: 208 | I15: 47 | J15: =YEAR(A15) -> 2015 | K15: =MONTH(A15) -> 2
A16: 42094 | B16: 156.04000000000005 | C16: 129.38599999999997 | D16: 133.8 | E16: 1084.8500000000001 | F16: 208 | G16: 13 | H16: 195 | I16: 54 | J16: =YEAR(A16) -> 2015 | K16: =MONTH(A16) -> 3
A17: 42124 | B17: 154.5 | C17: 101.115 | D17: 122.10000000000001 | E17: 940.1700000000001 | F17: 192 | G17: 5 | H17: 97 | I17: 112 | J17: =YEAR(A17) -> 2015 | K17: =MONTH(A17) -> 4
A18: 42155 | B18: 160.02 | C18: 119.11700000000006 | D18: 136.04 | E18: 765.9000000000001 | F18: 194 | G18: 10 | H18: 100 | I18: 159.5 | J18: =YEAR(A18) -> 2015 | K18: =MONTH(A18) -> 5
A19: 42185 | B19: 151.87000000000003 | C19: 113.69 | D19: 145.46 | E19: 746.788 | F19: 217 | G19: 12 | H19: 193 | I19: 125.79999999999998 | J19: =YEAR(A19) -> 2015 | K19: =MONTH(A19) -> 6
A20: 42216 | B20: 175.61000000000004 | C20: 113.81000000000002 | D20: 125.5 | E20: 708.8280000000001 | F20: 203 | G20: 6 | H20: 60 | I20: 130.3 | J20: =YEAR(A20) -> 2015 | K20: =MONTH(A20) -> 7
A21: 42247 | B21: 181.69000000000003 | C21: 144.51900000000003 | D21: 133.4 | E21: 790.788 | F21: 265.5 | G21: 15 | H21: 45 | I21: 83.7 | J21: =YEAR(A21) -> 2015 | K21: =MONTH(A21) -> 8
A22: 42277 | B22: 166.22000000000008 | C22: 134.12200000000004 | D22: 110.4 | E22: 852.125 | F22: 243.5 | G22: 11 | H22: 91 | I22: 71 | J22: =YEAR(A22) -> 2015 | K22: =MONTH(A22) -> 9
A23: 42308 | B23: 195.81000000000014 | C23: 127.23099999999998 | D23: 146.20000000000002 | E23: 1574.3350000000007 | F23: 222 | G23: 8 | H23: 184 | I23: 72 | J23: =YEAR(A23) -> 2015 | K23: =MONTH(A23) -> 10
A24: 42338 | B24: 152.78000000000006 | C24: 128.233 | D24: 145.90000000000003 | E24: 1277.725 | F24: 228 | G24: 18 | H24: 195 | I24: 44 | J24: =YEAR(A24) -> 2015 | K24: =MONTH(A24) -> 11
A25: 42369 | B25: 159.46000000000004 | C25: 131.29100000000003 | D25: 136.99999999999997 | E25: 1258.3490000000002 | F25: 286 | G25: 28 | H25: 231 | I25: 41.73 | J25: =YEAR(A25) -> 2015 | K25: =MONTH(A25) -> 12
A26: 42400 | B26: 171.65000000000006 | C26: 128.402 | D26: 172.49999999999997 | E26: 1476.3240000000003 | F26: 248 | G26: 24 | H26: 174 | I26: 56.5 | J26: =YEAR(A26) -> 2016 | K26: =MONTH(A26) -> 1
A27: 42429 | B27: 173.81000000000003 | C27: 137.528 | D27: 134.20000000000002 | E27: 1224.8620000000003 | F27: 239 | G27: 20 | H27: 245 | I27: 58 | J27: =YEAR(A27) -> 2016 | K27: =MONTH(A27) -> 2
A28: 42460 | B28: 156.64000000000004 | C28: 180.5890000000001 | D28: 148.4 | E28: 1150.7000000000003 | F28: 250 | G28: 13 | H28: 253 | I28: 97.84 | J28: =YEAR(A28) -> 2016 | K28: =MONTH(A28) -> 3
A29: 42490 | B29: 166.6100000000001 | C29: 146.52600000000007 | D29: 147.7 | E29: 998.3370000000003 | F29: 318 | G29: 18 | H29: 216 | I29: 162.39999999999998 | J29: =YEAR(A29) -> 2016 | K29: =MONTH(A29) -> 4
A30: 42521 | B30: 167.36000000000007 | C30: 120.86099999999996 | D30: 130.54999999999995 | E30: 997.1500000000003 | F30: 275 | G30: 18 | H30: 131 | I30: 137.10000000000002 | J30: =YEAR(A30) -> 2016 | K30: =MONTH(A30) -> 5
A31: 42551 | B31: 169.67000000000002 | C31: 114.961 | D31: 117.75 | E31: 760.05 | F31: 311 | G31: 20 | H31: 127 | I31: 134.8 | J31: =YEAR(A31) -> 2016 | K31: =MONTH(A31) -> 6
A32: 42582 | B32: 203.97000000000017 | C32: 141.01900000000003 | D32: 137.89999999999998 | E32: 652.3619999999999 | F32: 240 | G32: 8 | H32: 109 | I32: 116.83 | J32: =YEAR(A32) -> 2016 | K32: =MONTH(A32) -> 7
A33: 42613 | B33: 211.13000000000017 | C33: 114.37499999999997 | D33: 132.7 | E33: 753.0500000000002 | F33: 275.5 | G33: 12 | H33: 116 | I33: 85.3 | J33: =YEAR(A33) -> 2016 | K33: =MONTH(A33) -> 8
A34: 42643 | B34: 172.96000000000004 | C34: 126.21799999999995 | D34: 116.7 | E34: 1118.699 | F34: 307 | G34: 18 | H34: 121 | I34: 69.3 | J34: =YEAR(A34) -> 2016 | K34: =MONTH(A34) -> 9
A35: 42674 | B35: 186.7600000000001 | C35: 142.0560000000001 | D35: 160.15 | E35: 1617.275000000001 | F35: 312 | G35: 11 | H35: 220 | I35: 60.9 | J35: =YEAR(A35) -> 2016 | K35: =MONTH(A35) -> 10
A36: 42704 | B36: 175.18000000000012 | C36: 116.84999999999997 | D36: 133.85000000000002 | E36: 1062.6860000000004 | F36: 246 | G36: 27 | H36: 150 | I36: 51.199999999999996 | J36: =YEAR(A36) -> 2016 | K36: =MONTH(A36) -> 11
A37: 42735 | B37: 169.32000000000002 | C37: 135.05600000000004 | D37: 132.39999999999998 | E37: 1624.3350000000003 | F37: 257 | G37: 18 | H37: 275 | I37: 34.9 | J37: =YEAR(A37) -> 2016 | K37: =MONTH(A37) -> 12
A38: 42766 | B38: 0 | C38: 0 | D38: 0 | E38: 0 | F38: 1 | G38: 0 | H38: 0 | I38: 0 | J38: =YEAR(A38) -> 2017 | K38: =MONTH(A38) -> 1
A39: 42794 | B39: 139.69000000000003 | C39: 103.51700000000001 | D39: 97 | E39: 526.3500000000001 | F39: 144 | G39: 7 | H39: 117 | I39: 30.6 | J39: =YEAR(A39) -> 2017 | K39: =MONTH(A39) -> 2
A40: 42825 | B40: 162.85000000000002 | C40: 111.055 | D40: 107.35000000000001 | E40: 612.5000000000002 | F40: 165 | G40: 9 | H40: 139 | I40: 100.1 | J40: =YEAR(A40) -> 2017 | K40: =MONTH(A40) -> 3
...

Sheet fact_sales_monthly
A1: date | B1: year | C1: month | D1: drug_class | E1: units_sold
A2: {=INDEX(salesmonthly!$A$2:$A$5000, INT((ROW()-2)/8)+1)} -> 41670 | B2: {=INDEX(salesmonthly!$J$2:$J$5000, INT((ROW()-2)/8)+1)} -> 2014 | C2: {=INDEX(salesmonthly!$K$2:$K$5000, INT((ROW()-2)/8)+1)} -> 1 | D2: {=INDEX(salesmonthly!$B$1:$I$1, MOD(ROW()-2,8)+1)} -> M01AB | E2: {=INDEX(salesmonthly!$B$2:$I$5000, INT((ROW()-2)/8)+1, MOD(ROW()-2,8)+1)} -> 127.69000000000001
A3: {=INDEX(salesmonthly!$A$2:$A$5000, INT((ROW()-2)/8)+1)} -> 41670 | B3: {=INDEX(salesmonthly!$J$2:$J$5000, INT((ROW()-2)/8)+1)} -> 2014 | C3: {=INDEX(salesmonthly!$K$2:$K$5000, INT((ROW()-2)/8)+1)} -> 1 | D3: {=INDEX(salesmonthly!$B$1:$I$1, MOD(ROW()-2,8)+1)} -> M01AE | E3: {=INDEX(salesmonthly!$B$2:$I$5000, INT((ROW()-2)/8)+1, MOD(ROW()-2,8)+1)} -> 99.09000000000005
A4: {=INDEX(salesmonthly!$A$2:$A$5000, INT((ROW()-2)/8)+1)} -> 41670 | B4: {=INDEX(salesmonthly!$J$2:$J$5000, INT((ROW()-2)/8)+1)} -> 2014 | C4: {=INDEX(salesmonthly!$K$2:$K$5000, INT((ROW()-2)/8)+1)} -> 1 | D4: {=INDEX(salesmonthly!$B$1:$I$1, MOD(ROW()-2,8)+1)} -> N02BA | E4: {=INDEX(salesmonthly!$B$2:$I$5000, INT((ROW()-2)/8)+1, MOD(ROW()-2,8)+1)} -> 152.09999999999997
A5: {=INDEX(salesmonthly!$A$2:$A$5000, INT((ROW()-2)/8)+1)} -> 41670 | B5: {=INDEX(salesmonthly!$J$2:$J$5000, INT((ROW()-2)/8)+1)} -> 2014 | C5: {=INDEX(salesmonthly!$K$2:$K$5000, INT((ROW()-2)/8)+1)} -> 1 | D5: {=INDEX(salesmonthly!$B$1:$I$1, MOD(ROW()-2,8)+1)} -> N02BE | E5: {=INDEX(salesmonthly!$B$2:$I$5000, INT((ROW()-2)/8)+1, MOD(ROW()-2,8)+1)} -> 878.0300000000002
A6: {=INDEX(salesmonthly!$A$2:$A$5000, INT((ROW()-2)/8)+1)} -> 41670 | B6: {=INDEX(salesmonthly!$J$2:$J$5000, INT((ROW()-2)/8)+1)} -> 2014 | C6: {=INDEX(salesmonthly!$K$2:$K$5000, INT((ROW()-2)/8)+1)} -> 1 | D6: {=INDEX(salesmonthly!$B$1:$I$1, MOD(ROW()-2,8)+1)} -> N05B | E6: {=INDEX(salesmonthly!$B$2:$I$5000, INT((ROW()-2)/8)+1, MOD(ROW()-2,8)+1)} -> 354
A7: {=INDEX(salesmonthly!$A$2:$A$5000, INT((ROW()-2)/8)+1)} -> 41670 | B7: {=INDEX(salesmonthly!$J$2:$J$5000, INT((ROW()-2)/8)+1)} -> 2014 | C7: {=INDEX(salesmonthly!$K$2:$K$5000, INT((ROW()-2)/8)+1)} -> 1 | D7: {=INDEX(salesmonthly!$B$1:$I$1, MOD(ROW()-2,8)+1)} -> N05C | E7: {=INDEX(salesmonthly!$B$2:$I$5000, INT((ROW()-2)/8)+1, MOD(ROW()-2,8)+1)} -> 50
A8: {=INDEX(salesmonthly!$A$2:$A$5000, INT((ROW()-2)/8)+1)} -> 41670 | B8: {=INDEX(salesmonthly!$J$2:$J$5000, INT((ROW()-2)/8)+1)} -> 2014 | C8: {=INDEX(salesmonthly!$K$2:$K$5000, INT((ROW()-2)/8)+1)} -> 1 | D8: {=INDEX(salesmonthly!$B$1:$I$1, MOD(ROW()-2,8)+1)} -> R03 | E8: {=INDEX(salesmonthly!$B$2:$I$5000, INT((ROW()-2)/8)+1, MOD(ROW()-2,8)+1)} -> 112
A9: {=INDEX(salesmonthly!$A$2:$A$5000, INT((ROW()-2)/8)+1)} -> 41670 | B9: {=INDEX(salesmonthly!$J$2:$J$5000, INT((ROW()-2)/8)+1)} -> 2014 | C9: {=INDEX(salesmonthly!$K$2:$K$5000, INT((ROW()-2)/8)+1)} -> 1 | D9: {=INDEX(salesmonthly!$B$1:$I$1, MOD(ROW()-2,8)+1)} -> R06 | E9: {=INDEX(salesmonthly!$B$2:$I$5000, INT((ROW()-2)/8)+1, MOD(ROW()-2,8)+1)} -> 48.2
A10: {=INDEX(salesmonthly!$A$2:$A$5000, INT((ROW()-2)/8)+1)} -> 41698 | B10: {=INDEX(salesmonthly!$J$2:$J$5000, INT((ROW()-2)/8)+1)} -> 2014 | C10: {=INDEX(salesmonthly!$K$2:$K$5000, INT((ROW()-2)/8)+1)} -> 2 | D10: {=INDEX(salesmonthly!$B$1:$I$1, MOD(ROW()-2,8)+1)} -> M01AB | E10: {=INDEX(salesmonthly!$B$2:$I$5000, INT((ROW()-2)/8)+1, MOD(ROW()-2,8)+1)} -> 133.32
A11: {=INDEX(salesmonthly!$A$2:$A$5000, INT((ROW()-2)/8)+1)} -> 41698 | B11: {=INDEX(salesmonthly!$J$2:$J$5000, INT((ROW()-2)/8)+1)} -> 2014 | C11: {=INDEX(salesmonthly!$K$2:$K$5000, INT((ROW()-2)/8)+1)} -> 2 | D11: {=INDEX(salesmonthly!$B$1:$I$1, MOD(ROW()-2,8)+1)} -> M01AE | E11: {=INDEX(salesmonthly!$B$2:$I$5000, INT((ROW()-2)/8)+1, MOD(ROW()-2,8)+1)} -> 126.0500000000001
A12: {=INDEX(salesmonthly!$A$2:$A$5000, INT((ROW()-2)/8)+1)} -> 41698 | B12: {=INDEX(salesmonthly!$J$2:$J$5000, INT((ROW()-2)/8)+1)} -> 2014 | C12: {=INDEX(salesmonthly!$K$2:$K$5000, INT((ROW()-2)/8)+1)} -> 2 | D12: {=INDEX(salesmonthly!$B$1:$I$1, MOD(ROW()-2,8)+1)} -> N02BA | E12: {=INDEX(salesmonthly!$B$2:$I$5000, INT((ROW()-2)/8)+1, MOD(ROW()-2,8)+1)} -> 176.99999999999997
A13: {=INDEX(salesmonthly!$A$2:$A$5000, INT((ROW()-2)/8)+1)} -> 41698 | B13: {=INDEX(salesmonthly!$J$2:$J$5000, INT((ROW()-2)/8)+1)} -> 2014 | C13: {=INDEX(salesmonthly!$K$2:$K$5000, INT((ROW()-2)/8)+1)} -> 2 | D13: {=INDEX(salesmonthly!$B$1:$I$1, MOD(ROW()-2,8)+1)} -> N02BE | E13: {=INDEX(salesmonthly!$B$2:$I$5000, INT((ROW()-2)/8)+1, MOD(ROW()-2,8)+1)} -> 1001.9000000000001
... A561: {=INDEX(salesmonthly!$A$2:$A$5000, INT((ROW()-2)/8)+1)} -> 43769 | B561: {=INDEX(salesmonthly!$J$2:$J$5000, INT((ROW()-2)/8)+1)} -> 2019 | C561: {=INDEX(salesmonthly!$K$2:$K$5000, INT((ROW()-2)/8)+1)} -> 10 | D561: {=INDEX(salesmonthly!$B$1:$I$1, MOD(ROW()-2,8)+1)} -> R06 | E561: {=INDEX(salesmonthly!$B$2:$I$5000, INT((ROW()-2)/8)+1, MOD(ROW()-2,8)+1)} -> 11.129999999999999

Sheet monthly_financials
A1: year | B1: month | C1: drug_class | D1: monthly_units | E1: revenue | F1: profit | G1: year_month
A2: 2014 | B2: 1 | C2: M01AB | D2: =SUMIFS( fact_sales_monthly!$E:$E, fact_sales_monthly!$B:$B, A2, fact_sales_monthly!$C:$C, B2, fact_sales_monthly!$D:$D, C2 ) -> 0 | E2: =D2 * 1 -> 0 | F2: =D2 * 0.25 -> 0 | G2: =TEXT(DATE(A2, B2, 1), "yyyy-mm") -> 2014-01
A3: 2014 | B3: 1 | C3: M01AE | D3: =SUMIFS( fact_sales_monthly!$E:$E, fact_sales_monthly!$B:$B, A3, fact_sales_monthly!$C:$C, B3, fact_sales_monthly!$D:$D, C3 ) -> 0 | E3: =D3 * 1 -> 0 | F3: =D3 * 0.25 -> 0 | G3: =TEXT(DATE(A3, B3, 1), "yyyy-mm") -> 2014-01
A4: 2014 | B4: 1 | C4: N02BA | D4: =SUMIFS( fact_sales_monthly!$E:$E, fact_sales_monthly!$B:$B, A4, fact_sales_monthly!$C:$C, B4, fact_sales_monthly!$D:$D, C4 ) -> 0 | E4: =D4 * 1 -> 0 | F4: =D4 * 0.25 -> 0 | G4: =TEXT(DATE(A4, B4, 1), "yyyy-mm") -> 2014-01
A5: 2014 | B5: 1 | C5: N02BE | D5: =SUMIFS( fact_sales_monthly!$E:$E, fact_sales_monthly!$B:$B, A5, fact_sales_monthly!$C:$C, B5, fact_sales_monthly!$D:$D, C5 ) -> 0 | E5: =D5 * 1 -> 0 | F5: =D5 * 0.25 -> 0 | G5: =TEXT(DATE(A5, B5, 1), "yyyy-mm") -> 2014-01
A6: 2014 | B6: 1 | C6: N05B | D6: =SUMIFS( fact_sales_monthly!$E:$E, fact_sales_monthly!$B:$B, A6, fact_sales_monthly!$C:$C, B6, fact_sales_monthly!$D:$D, C6 ) -> 354 | E6: =D6 * 1 -> 354 | F6: =D6 * 0.25 -> 88.5 | G6: =TEXT(DATE(A6, B6, 1), "yyyy-mm") -> 2014-01
A7: 2014 | B7: 1 | C7: N05C | D7: =SUMIFS( fact_sales_monthly!$E:$E, fact_sales_monthly!$B:$B, A7, fact_sales_monthly!$C:$C, B7, fact_sales_monthly!$D:$D, C7 ) -> 50 | E7: =D7 * 1 -> 50 | F7: =D7 * 0.25 -> 12.5 | G7: =TEXT(DATE(A7, B7, 1), "yyyy-mm") -> 2014-01
A8: 2014 | B8: 1 | C8: R03 | D8: =SUMIFS( fact_sales_monthly!$E:$E, fact_sales_monthly!$B:$B, A8, fact_sales_monthly!$C:$C, B8, fact_sales_monthly!$D:$D, C8 ) -> 112 | E8: =D8 * 1 -> 112 | F8: =D8 * 0.25 -> 28 | G8: =TEXT(DATE(A8, B8, 1), "yyyy-mm") -> 2014-01
A9: 2014 | B9: 1 | C9: R06 | D9: =SUMIFS( fact_sales_monthly!$E:$E, fact_sales_monthly!$B:$B, A9, fact_sales_monthly!$C:$C, B9, fact_sales_monthly!$D:$D, C9 ) -> 48.2 | E9: =D9 * 1 -> 48.2 | F9: =D9 * 0.25 -> 12.05 | G9: =TEXT(DATE(A9, B9, 1), "yyyy-mm") -> 2014-01
A10: 2014 | B10: 2 | C10: M01AB | D10: =SUMIFS( fact_sales_monthly!$E:$E, fact_sales_monthly!$B:$B, A10, fact_sales_monthly!$C:$C, B10, fact_sales_monthly!$D:$D, C10 ) -> 133.32 | E10: =D10 * 1 -> 133.32 | F10: =D10 * 0.25 -> 33.33 | G10: =TEXT(DATE(A10, B10, 1), "yyyy-mm") -> 2014-02
A11: 2014 | B11: 2 | C11: M01AE | D11: =SUMIFS( fact_sales_monthly!$E:$E, fact_sales_monthly!$B:$B, A11, fact_sales_monthly!$C:$C, B11, fact_sales_monthly!$D:$D, C11 ) -> 0 | E11: =D11 * 1 -> 0 | F11: =D11 * 0.25 -> 0 | G11: =TEXT(DATE(A11, B11, 1), "yyyy-mm") -> 2014-02
A12: 2014 | B12: 2 | C12: N02BA | D12: =SUMIFS( fact_sales_monthly!$E:$E, fact_sales_monthly!$B:$B, A12, fact_sales_monthly!$C:$C, B12, fact_sales_monthly!$D:$D, C12 ) -> 0 | E12: =D12 * 1 -> 0 | F12: =D12 * 0.25 -> 0 | G12: =TEXT(DATE(A12, B12, 1), "yyyy-mm") -> 2014-02
A13: 2014 | B13: 2 | C13: N02BE | D13: =SUMIFS( fact_sales_monthly!$E:$E, fact_sales_monthly!$B:$B, A13, fact_sales_monthly!$C:$C, B13, fact_sales_monthly!$D:$D, C13 ) -> 0 | E13: =D13 * 1 -> 0 | F13: =D13 * 0.25 -> 0 | G13: =TEXT(DATE(A13, B13, 1), "yyyy-mm") -> 2014-02
... A561: 2019 | B561: 10 | C561: R06 | D561: =SUMIFS( fact_sales_monthly!$E:$E, fact_sales_monthly!$B:$B, A561, fact_sales_monthly!$C:$C, B561, fact_sales_monthly!$D:$D, C561 ) -> 0 | E561: =D561 * 1 -> 0 | F561: =D561 * 0.25 -> 0 | G561: =TEXT(DATE(A561, B561, 1), "yyyy-mm") -> 2019-10

Sheet monthly_profit_summary
A1: year_month | B1: total_revenue | C1: total_profit
A2: 2014-01 | B2: =SUMIFS( monthly_financials!$E:$E, monthly_financials!$G:$G, A2 ) -> 564.2 | C2: =SUMIFS( monthly_financials!$F:$F, monthly_financials!$G:$G, A2 ) -> 141.05
A3: 2014-02 | B3: =SUMIFS( monthly_financials!$E:$E, monthly_financials!$G:$G, A3 ) -> 669.52 | C3: =SUMIFS( monthly_financials!$F:$F, monthly_financials!$G:$G, A3 ) -> 167.38
A4: 2014-03 | B4: =SUMIFS( monthly_financials!$E:$E, monthly_financials!$G:$G, A4 ) -> 1376.33 | C4: =SUMIFS( monthly_financials!$F:$F, monthly_financials!$G:$G, A4 ) -> 344.0825
A5: 2014-04 | B5: =SUMIFS( monthly_financials!$E:$E, monthly_financials!$G:$G, A5 ) -> 1096.2 | C5: =SUMIFS( monthly_financials!$F:$F, monthly_financials!$G:$G, A5 ) -> 274.05
A6: 2014-05 | B6: =SUMIFS( monthly_financials!$E:$E, monthly_financials!$G:$G, A6 ) -> 532.1 | C6: =SUMIFS( monthly_financials!$F:$F, monthly_financials!$G:$G, A6 ) -> 133.025
A7: 2014-06 | B7: =SUMIFS( monthly_financials!$E:$E, monthly_financials!$G:$G, A7 ) -> 1183.425 | C7: =SUMIFS( monthly_financials!$F:$F, monthly_financials!$G:$G, A7 ) -> 295.85625
A8: 2014-07 | B8: =SUMIFS( monthly_financials!$E:$E, monthly_financials!$G:$G, A8 ) -> 1120.3 | C8: =SUMIFS( monthly_financials!$F:$F, monthly_financials!$G:$G, A8 ) -> 280.075
A9: 2014-08 | B9: =SUMIFS( monthly_financials!$E:$E, monthly_financials!$G:$G, A9 ) -> 709.58 | C9: =SUMIFS( monthly_financials!$F:$F, monthly_financials!$G:$G, A9 ) -> 177.395
A10: 2014-09 | B10: =SUMIFS( monthly_financials!$E:$E, monthly_financials!$G:$G, A10 ) -> 586.8 | C10: =SUMIFS( monthly_financials!$F:$F, monthly_financials!$G:$G, A10 ) -> 146.7
A11: 2014-10 | B11: =SUMIFS( monthly_financials!$E:$E, monthly_financials!$G:$G, A11 ) -> 758.5 | C11: =SUMIFS( monthly_financials!$F:$F, monthly_financials!$G:$G, A11 ) -> 189.625
A12: 2014-11 | B12: =SUMIFS( monthly_financials!$E:$E, monthly_financials!$G:$G, A12 ) -> 1531.7 | C12: =SUMIFS( monthly_financials!$F:$F, monthly_financials!$G:$G, A12 ) -> 382.925
A13: 2014-12 | B13: =SUMIFS( monthly_financials!$E:$E, monthly_financials!$G:$G, A13 ) -> 713.4 | C13: =SUMIFS( monthly_financials!$F:$F, monthly_financials!$G:$G, A13 ) -> 178.35
... A71: 2019-10 | B71: =SUMIFS( monthly_financials!$E:$E, monthly_financials!$G:$G, A71 ) -> 187.95 | C71: =SUMIFS( monthly_financials!$F:$F, monthly_financials!$G:$G, A71 ) -> 46.9875
