Workbook

Sheet salesdaily
A1: datum | B1: M01AB | C1: M01AE | D1: N02BA | E1: N02BE | F1: N05B | G1: N05C | H1: R03 | I1: R06 | J1: Year | K1: Month | L1: Hour | M1: Weekday Name
A2: 41671 | B2: 0 | C2: 3.67 | D2: 3.4 | E2: 32.4 | F2: 7 | G2: 0 | H2: 0 | I2: 2 | J2: 2014 | K2: 1 | L2: 248 | M2: Thursday
A3: 41699 | B3: 8 | C3: 4 | D3: 4.4 | E3: 50.6 | F3: 16 | G3: 0 | H3: 20 | I3: 4 | J3: 2014 | K3: 1 | L3: 276 | M3: Friday
A4: 41730 | B4: 2 | C4: 1 | D4: 6.5 | E4: 61.85 | F4: 10 | G4: 0 | H4: 9 | I4: 1 | J4: 2014 | K4: 1 | L4: 276 | M4: Saturday
A5: 41760 | B5: 4 | C5: 3 | D5: 7 | E5: 41.1 | F5: 8 | G5: 0 | H5: 3 | I5: 0 | J5: 2014 | K5: 1 | L5: 276 | M5: Sunday
A6: 41791 | B6: 5 | C6: 1 | D6: 4.5 | E6: 21.7 | F6: 16 | G6: 2 | H6: 6 | I6: 2 | J6: 2014 | K6: 1 | L6: 276 | M6: Monday
A7: 41821 | B7: 0 | C7: 0 | D7: 0 | E7: 0 | F7: 0 | G7: 0 | H7: 0 | I7: 0 | J7: 2014 | K7: 1 | L7: 276 | M7: Tuesday
A8: 41852 | B8: 5.33 | C8: 3 | D8: 10.5 | E8: 26.4 | F8: 19 | G8: 1 | H8: 10 | I8: 0 | J8: 2014 | K8: 1 | L8: 276 | M8: Wednesday
A9: 41883 | B9: 7 | C9: 1.68 | D9: 8 | E9: 25 | F9: 16 | G9: 0 | H9: 3 | I9: 2 | J9: 2014 | K9: 1 | L9: 276 | M9: Thursday
A10: 41913 | B10: 5 | C10: 2 | D10: 2 | E10: 53.3 | F10: 15 | G10: 2 | H10: 0 | I10: 2 | J10: 2014 | K10: 1 | L10: 276 | M10: Friday
A11: 41944 | B11: 5 | C11: 4.34 | D11: 10.4 | E11: 52.3 | F11: 14 | G11: 0 | H11: 1 | I11: 0.2 | J11: 2014 | K11: 1 | L11: 276 | M11: Saturday
A12: 41974 | B12: 2 | C12: 0.66 | D12: 2.5 | E12: 12 | F12: 8 | G12: 0 | H12: 1 | I12: 1 | J12: 2014 | K12: 1 | L12: 276 | M12: Sunday
A13: 1/13/2014 | B13: 7.34 | C13: 7.66 | D13: 6.2 | E13: 52 | F13: 9 | G13: 0 | H13: 7 | I13: 1 | J13: 2014 | K13: 1 | L13: 276 | M13: Monday
A14: 1/14/2014 | B14: 6 | C14: 1.33 | D14: 12.3 | E14: 33.7 | F14: 6 | G14: 1 | H14: 0 | I14: 2 | J14: 2014 | K14: 1 | L14: 276 | M14: Tuesday
A15: 1/15/2014 | B15: 4 | C15: 2.34 | D15: 5 | E15: 26.7 | F15: 12 | G15: 2 | H15: 3 | I15: 3 | J15: 2014 | K15: 1 | L15: 276 | M15: Wednesday
A16: 1/16/2014 | B16: 6 | C16: 2 | D16: 4.3 | E16: 28.3 | F16: 19 | G16: 1 | H16: 5 | I16: 0 | J16: 2014 | K16: 1 | L16: 276 | M16: Thursday
A17: 1/17/2014 | B17: 2 | C17: 3.68 | D17: 8.3 | E17: 20.4 | F17: 15 | G17: 0 | H17: 6 | I17: 3 | J17: 2014 | K17: 1 | L17: 276 | M17: Friday
A18: 1/18/2014 | B18: 1 | C18: 5.33 | D18: 5.8 | E18: 43.2 | F18: 15 | G18: 4 | H18: 7 | I18: 2 | J18: 2014 | K18: 1 | L18: 276 | M18: Saturday
A19: 1/19/2014 | B19: 4.33 | C19: 4 | D19: 4 | E19: 14.1 | F19: 4 | G19: 0 | H19: 1 | I19: 1 | J19: 2014 | K19: 1 | L19: 276 | M19: Sunday
A20: 1/20/2014 | B20: 6 | C20: 3.34 | D20: 3.3 | E20: 11.9 | F20: 18 | G20: 2 | H20: 12 | I20: 3 | J20: 2014 | K20: 1 | L20: 276 | M20: Monday
A21: 1/21/2014 | B21: 2 | C21: 3.34 | D21: 4 | E21: 42 | F21: 15 | G21: 2 | H21: 0 | I21: 1 | J21: 2014 | K21: 1 | L21: 276 | M21: Tuesday
A22: 1/22/2014 | B22: 7 | C22: 3 | D22: 7 | E22: 18.1 | F22: 10 | G22: 0 | H22: 5 | I22: 2 | J22: 2014 | K22: 1 | L22: 276 | M22: Wednesday
A23: 1/23/2014 | B23: 4 | C23: 4.67 | D23: 5.2 | E23: 26.2 | F23: 2 | G23: 3 | H23: 1 | I23: 3 | J23: 2014 | K23: 1 | L23: 276 | M23: Thursday
A24: 1/24/2014 | B24: 4.67 | C24: 7.34 | D24: 7 | E24: 19.6 | F24: 13 | G24: 1 | H24: 0 | I24: 0 | J24: 2014 | K24: 1 | L24: 276 | M24: Friday
... A31: 1/31/2014 | B31: 1 | C31: 2.68 | D31: 7.1 | E31: 26.9 | F31: 9 | G31: 0 | H31: 1 | I31: 0 | J31: 2014 | K31: 1 | L31: 276 | M31: Friday
A32: 41641 | B32: 4.33 | C32: 4.32 | D32: 5 | E32: 43 | F32: 13 | G32: 1 | H32: 14 | I32: 0 | J32: 2014 | K32: 2 | L32: 276 | M32: Saturday
A33: 41672 | B33: 7 | C33: 3 | D33: 0.2 | E33: 13.5 | F33: 6 | G33: 2 | H33: 8 | I33: 0 | J33: 2014 | K33: 2 | L33: 276 | M33: Sunday
A34: 41700 | B34: 5 | C34: 1 | D34: 8.5 | E34: 32.4 | F34: 16 | G34: 1 | H34: 1 | I34: 0 | J34: 2014 | K34: 2 | L34: 276 | M34: Monday
A35: 41731 | B35: 1.33 | C35: 3 | D35: 7 | E35: 30.6 | F35: 8 | G35: 1 | H35: 17 | I35: 2 | J35: 2014 | K35: 2 | L35: 276 | M35: Tuesday
A36: 41761 | B36: 3 | C36: 4.02 | D36: 6.2 | E36: 32.4 | F36: 15 | G36: 1 | H36: 1 | I36: 1 | J36: 2014 | K36: 2 | L36: 276 | M36: Wednesday
A37: 41792 | B37: 3.33 | C37: 6.68 | D37: 3.5 | E37: 41.4 | F37: 17 | G37: 2 | H37: 5 | I37: 2 | J37: 2014 | K37: 2 | L37: 276 | M37: Thursday
A38: 41822 | B38: 2.66 | C38: 8.67 | D38: 11.7 | E38: 21.4 | F38: 19 | G38: 1 | H38: 0 | I38: 0 | J38: 2014 | K38: 2 | L38: 276 | M38: Friday
A39: 41853 | B39: 3.33 | C39: 3.35 | D39: 14.4 | E39: 37.1 | F39: 13 | G39: 1 | H39: 1 | I39: 1 | J39: 2014 | K39: 2 | L39: 276 | M39: Saturday
A40: 41884 | B40: 4 | C40: 3 | D40: 2 | E40: 31.5 | F40: 10 | G40: 0 | H40: 6 | I40: 0 | J40: 2014 | K40: 2 | L40: 276 | M40: Sunday
A41: 41914 | B41: 5 | C41: 10.33 | D41: 8.5 | E41: 40.1 | F41: 20 | G41: 3 | H41: 3 | I41: 1 | J41: 2014 | K41: 2 | L41: 276 | M41: Monday
A42: 41945 | B42: 10 | C42: 6.99 | D42: 13.3 | E42: 44.6 | F42: 20 | G42: 2 | H42: 6 | I42: 2.2 | J42: 2014 | K42: 2 | L42: 276 | M42: Tuesday
A43: 41975 | B43: 9 | C43: 1.67 | D43: 9.1 | E43: 73.6 | F43: 9 | G43: 0 | H43: 5 | I43: 0 | J43: 2014 | K43: 2 | L43: 276 | M43: Wednesday
A44: 2/13/2014 | B44: 4.33 | C44: 3.67 | D44: 10 | E44: 49.1 | F44: 13 | G44: 3 | H44: 0 | I44: 1 | J44: 2014 | K44: 2 | L44: 276 | M44: Thursday
A45: 2/14/2014 | B45: 4 | C45: 4.01 | D45: 3.2 | E45: 42.3 | F45: 13 | G45: 4 | H45: 0 | I45: 6 | J45: 2014 | K45: 2 | L45: 276 | M45: Friday
A46: 2/15/2014 | B46: 1 | C46: 2.34 | D46: 2 | E46: 37 | F46: 9 | G46: 0 | H46: 1 | I46: 5 | J46: 2014 | K46: 2 | L46: 276 | M46: Saturday
...

Sheet fact_sales_daily_final
A1: date | B1: year | C1: month | D1: weekday | E1: drug_class | F1: units_sold
A2: 41671 | B2: 2014 | C2: 1 | D2: Thursday | E2: M01AB | F2: 0
A3: 41671 | B3: 2014 | C3: 1 | D3: Thursday | E3: M01AE | F3: 3.67
A4: 41671 | B4: 2014 | C4: 1 | D4: Thursday | E4: N02BA | F4: 3.4
A5: 41671 | B5: 2014 | C5: 1 | D5: Thursday | E5: N02BE | F5: 32.4
A6: 41671 | B6: 2014 | C6: 1 | D6: Thursday | E6: N05B | F6: 7
A7: 41671 | B7: 2014 | C7: 1 | D7: Thursday | E7: N05C | F7: 0
A8: 41671 | B8: 2014 | C8: 1 | D8: Thursday | E8: R03 | F8: 0
A9: 41671 | B9: 2014 | C9: 1 | D9: Thursday | E9: R06 | F9: 2
A10: 41699 | B10: 2014 | C10: 1 | D10: Friday | E10: M01AB | F10: 8
A11: 41699 | B11: 2014 | C11: 1 | D11: Friday | E11: M01AE | F11: 4
A12: 41699 | B12: 2014 | C12: 1 | D12: Friday | E12: N02BA | F12: 4.4
A13: 41699 | B13: 2014 | C13: 1 | D13: Friday | E13: N02BE | F13: 50.6
... A89: 41974 | B89: 2014 | C89: 1 | D89: Sunday | E89: R06 | F89: 1
A90: 1/13/2014 | B90: 2014 | C90: 1 | D90: Monday | E90: M01AB | F90: 7.34
A91: 1/13/2014 | B91: 2014 | C91: 1 | D91: Monday | E91: M01AE | F91: 7.66
A92: 1/13/2014 | B92: 2014 | C92: 1 | D92: Monday | E92: N02BA | F92: 6.2
A93: 1/13/2014 | B93: 2014 | C93: 1 | D93: Monday | E93: N02BE | F93: 52
A94: 1/13/2014 | B94: 2014 | C94: 1 | D94: Monday | E94: N05B | F94: 9
A95: 1/13/2014 | B95: 2014 | C95: 1 | D95: Monday | E95: N05C | F95: 0
A96: 1/13/2014 | B96: 2014 | C96: 1 | D96: Monday | E96: R03 | F96: 7
A97: 1/13/2014 | B97: 2014 | C97: 1 | D97: Monday | E97: R06 | F97: 1
A98: 1/14/2014 | B98: 2014 | C98: 1 | D98: Tuesday | E98: M01AB | F98: 6
A99: 1/14/2014 | B99: 2014 | C99: 1 | D99: Tuesday | E99: M01AE | F99: 1.33
A100: 1/14/2014 | B100: 2014 | C100: 1 | D100: Tuesday | E100: N02BA | F100: 12.3
A101: 1/14/2014 | B101: 2014 | C101: 1 | D101: Tuesday | E101: N02BE | F101: 33.7
... A241: 1/31/2014 | B241: 2014 | C241: 1 | D241: Friday | E241: R06 | F241: 0
A242: 41641 | B242: 2014 | C242: 2 | D242: Saturday | E242: M01AB | F242: 4.33
A243: 41641 | B243: 2014 | C243: 2 | D243: Saturday | E243: M01AE | F243: 4.32
A244: 41641 | B244: 2014 | C244: 2 | D244: Saturday | E244: N02BA | F244: 5
A245: 41641 | B245: 2014 | C245: 2 | D245: Saturday | E245: N02BE | F245: 43
A246: 41641 | B246: 2014 | C246: 2 | D246: Saturday | E246: N05B | F246: 13
A247: 41641 | B247: 2014 | C247: 2 | D247: Saturday | E247: N05C | F247: 1
A248: 41641 | B248: 2014 | C248: 2 | D248: Saturday | E248: R03 | F248: 14
A249: 41641 | B249: 2014 | C249: 2 | D249: Saturday | E249: R06 | F249: 0
A250: 41672 | B250: 2014 | C250: 2 | D250: Sunday | E250: M01AB | F250: 7
A251: 41672 | B251: 2014 | C251: 2 | D251: Sunday | E251: M01AE | F251: 3
A252: 41672 | B252: 2014 | C252: 2 | D252: Sunday | E252: N02BA | F252: 0.2
A253: 41672 | B253: 2014 | C253: 2 | D253: Sunday | E253: N02BE | F253: 13.5
... A337: 41975 | B337: 2014 | C337: 2 | D337: Wednesday | E337: R06 | F337: 0
...

Sheet dim_drug_class
A1: drug_class | B1: therapy_area
A2: M01AB | B2: Anti-inflammatory & antirheumatic
A3: M01AE | B3: Anti-inflammatory & antirheumatic
A4: N02BA | B4: Analgesics
A5: N02BE | B5: Paracetamol-type analgesics
A6: N05B | B6: Anxiolytics
A7: N05C | B7: Hypnotics & sedatives
A8: R03 | B8: Airway disease drugs
A9: R06 | B9: Antihistamines

Sheet daily_demand_metrics
A1: drug_class | B1: avg_daily_units | C1: demand_std_dev | D1: volatility_index | E1: stability_score | F1: risk_category
A2: M01AB | B2: =AVERAGEIFS( fact_sales_daily_final!$F:$F, fact_sales_daily_final!$E:$E, A2 ) -> 5.0336833 | C2: {=_xlfn.STDEV.P( _xlfn._xlws.FILTER( fact_sales_daily_final!$F:$F, fact_sales_daily_final!$E:$E = A2 ) )} -> 2.7369285 | D2: =C2 / B2 -> 0.54372282 | E2: =MAX(0, 1 - D2) -> 0.45627718 | F2: =IF(D2>1,"High Risk", IF(D2>0.6,"Moderate Risk", "Low Risk")) -> Low Risk
A3: M01AE | B3: =AVERAGEIFS( fact_sales_daily_final!$F:$F, fact_sales_daily_final!$E:$E, A3 ) -> 3.8958303 | C3: {=_xlfn.STDEV.P( _xlfn._xlws.FILTER( fact_sales_daily_final!$F:$F, fact_sales_daily_final!$E:$E = A3 ) )} -> 2.13283 | D3: =C3 / B3 -> 0.54746482 | E3: =MAX(0, 1 - D3) -> 0.45253518 | F3: =IF(D3>1,"High Risk", IF(D3>0.6,"Moderate Risk", "Low Risk")) -> Low Risk
A4: N02BA | B4: =AVERAGEIFS( fact_sales_daily_final!$F:$F, fact_sales_daily_final!$E:$E, A4 ) -> 3.8804411 | C4: {=_xlfn.STDEV.P( _xlfn._xlws.FILTER( fact_sales_daily_final!$F:$F, fact_sales_daily_final!$E:$E = A4 ) )} -> 2.3834442 | D4: =C4 / B4 -> 0.6142199 | E4: =MAX(0, 1 - D4) -> 0.3857801 | F4: =IF(D4>1,"High Risk", IF(D4>0.6,"Moderate Risk", "Low Risk")) -> Moderate Risk
A5: N02BE | B5: =AVERAGEIFS( fact_sales_daily_final!$F:$F, fact_sales_daily_final!$E:$E, A5 ) -> 29.917095 | C5: {=_xlfn.STDEV.P( _xlfn._xlws.FILTER( fact_sales_daily_final!$F:$F, fact_sales_daily_final!$E:$E = A5 ) )} -> 15.587264 | D5: =C5 / B5 -> 0.52101527 | E5: =MAX(0, 1 - D5) -> 0.47898473 | F5: =IF(D5>1,"High Risk", IF(D5>0.6,"Moderate Risk", "Low Risk")) -> Low Risk
A6: N05B | B6: =AVERAGEIFS( fact_sales_daily_final!$F:$F, fact_sales_daily_final!$E:$E, A6 ) -> 8.8536265 | C6: {=_xlfn.STDEV.P( _xlfn._xlws.FILTER( fact_sales_daily_final!$F:$F, fact_sales_daily_final!$E:$E = A6 ) )} -> 5.6042737 | D6: =C6 / B6 -> 0.63299188 | E6: =MAX(0, 1 - D6) -> 0.36700812 | F6: =IF(D6>1,"High Risk", IF(D6>0.6,"Moderate Risk", "Low Risk")) -> Moderate Risk
A7: N05C | B7: =AVERAGEIFS( fact_sales_daily_final!$F:$F, fact_sales_daily_final!$E:$E, A7 ) -> 0.59352248 | C7: {=_xlfn.STDEV.P( _xlfn._xlws.FILTER( fact_sales_daily_final!$F:$F, fact_sales_daily_final!$E:$E = A7 ) )} -> 1.0927288 | D7: =C7 / B7 -> 1.8410908 | E7: =MAX(0, 1 - D7) -> 0 | F7: =IF(D7>1,"High Risk", IF(D7>0.6,"Moderate Risk", "Low Risk")) -> High Risk
A8: R03 | B8: =AVERAGEIFS( fact_sales_daily_final!$F:$F, fact_sales_daily_final!$E:$E, A8 ) -> 5.5122616 | C8: {=_xlfn.STDEV.P( _xlfn._xlws.FILTER( fact_sales_daily_final!$F:$F, fact_sales_daily_final!$E:$E = A8 ) )} -> 6.4272099 | D8: =C8 / B8 -> 1.1659842 | E8: =MAX(0, 1 - D8) -> 0 | F8: =IF(D8>1,"High Risk", IF(D8>0.6,"Moderate Risk", "Low Risk")) -> High Risk
A9: R06 | B9: =AVERAGEIFS( fact_sales_daily_final!$F:$F, fact_sales_daily_final!$E:$E, A9 ) -> 2.9001982 | C9: {=_xlfn.STDEV.P( _xlfn._xlws.FILTER( fact_sales_daily_final!$F:$F, fact_sales_daily_final!$E:$E = A9 ) )} -> 2.4152423 | D9: =C9 / B9 -> 0.83278524 | E9: =MAX(0, 1 - D9) -> 0.16721476 | F9: =IF(D9>1,"High Risk", IF(D9>0.6,"Moderate Risk", "Low Risk")) -> Moderate Risk

Sheet finance_assumptions
A1: drug_claas | B1: unit_price | D1: Cost Type | E1: % of Revenue
A2: M01AB | B2: 1 | D2: Manufacturing | E2: 0.55
A3: M01AE | B3: 1 | D3: Distribution | E3: 0.08
A4: N02BA | B4: 1 | D4: Marketing | E4: 0.12
A5: N02BE | B5: 1 | D5: Total Cost % | E5: 0.75
A6: N05B | B6: 1
A7: N05C | B7: 1
A8: R03 | B8: 1
A9: R06 | B9: 1

Sheet daily_financials
A1: date | B1: drug_class | C1: units_sold | D1: revenue | E1: total_cost | F1: profit | G1: profit_margin
A2: =fact_sales_daily_final!A2 -> 41671 | B2: =fact_sales_daily_final!E2 -> M01AB | C2: =fact_sales_daily_final!F2 -> 0 | D2: =C2 * VLOOKUP(B2, finance_assumptions!A:B, 2, FALSE) -> 0 | E2: =D2 * 0.75 -> 0 | F2: =D2 - E2 -> 0 | G2: =IF(D2=0, 0, F2/D2) -> 0
A3: =fact_sales_daily_final!A3 -> 41671 | B3: =fact_sales_daily_final!E3 -> M01AE | C3: =fact_sales_daily_final!F3 -> 3.67 | D3: =C3 * VLOOKUP(B3, finance_assumptions!A:B, 2, FALSE) -> 3.67 | E3: =D3 * 0.75 -> 2.7525 | F3: =D3 - E3 -> 0.9175 | G3: =IF(D3=0, 0, F3/D3) -> 0.25
A4: =fact_sales_daily_final!A4 -> 41671 | B4: =fact_sales_daily_final!E4 -> N02BA | C4: =fact_sales_daily_final!F4 -> 3.4 | D4: =C4 * VLOOKUP(B4, finance_assumptions!A:B, 2, FALSE) -> 3.4 | E4: =D4 * 0.75 -> 2.55 | F4: =D4 - E4 -> 0.85 | G4: =IF(D4=0, 0, F4/D4) -> 0.25
A5: =fact_sales_daily_final!A5 -> 41671 | B5: =fact_sales_daily_final!E5 -> N02BE | C5: =fact_sales_daily_final!F5 -> 32.4 | D5: =C5 * VLOOKUP(B5, finance_assumptions!A:B, 2, FALSE) -> 32.4 | E5: =D5 * 0.75 -> 24.3 | F5: =D5 - E5 -> 8.1 | G5: =IF(D5=0, 0, F5/D5) -> 0.25
A6: =fact_sales_daily_final!A6 -> 41671 | B6: =fact_sales_daily_final!E6 -> N05B | C6: =fact_sales_daily_final!F6 -> 7 | D6: =C6 * VLOOKUP(B6, finance_assumptions!A:B, 2, FALSE) -> 7 | E6: =D6 * 0.75 -> 5.25 | F6: =D6 - E6 -> 1.75 | G6: =IF(D6=0, 0, F6/D6) -> 0.25
A7: =fact_sales_daily_final!A7 -> 41671 | B7: =fact_sales_daily_final!E7 -> N05C | C7: =fact_sales_daily_final!F7 -> 0 | D7: =C7 * VLOOKUP(B7, finance_assumptions!A:B, 2, FALSE) -> 0 | E7: =D7 * 0.75 -> 0 | F7: =D7 - E7 -> 0 | G7: =IF(D7=0, 0, F7/D7) -> 0
A8: =fact_sales_daily_final!A8 -> 41671 | B8: =fact_sales_daily_final!E8 -> R03 | C8: =fact_sales_daily_final!F8 -> 0 | D8: =C8 * VLOOKUP(B8, finance_assumptions!A:B, 2, FALSE) -> 0 | E8: =D8 * 0.75 -> 0 | F8: =D8 - E8 -> 0 | G8: =IF(D8=0, 0, F8/D8) -> 0
A9: =fact_sales_daily_final!A9 -> 41671 | B9: =fact_sales_daily_final!E9 -> R06 | C9: =fact_sales_daily_final!F9 -> 2 | D9: =C9 * VLOOKUP(B9, finance_assumptions!A:B, 2, FALSE) -> 2 | E9: =D9 * 0.75 -> 1.5 | F9: =D9 - E9 -> 0.5 | G9: =IF(D9=0, 0, F9/D9) -> 0.25
A10: =fact_sales_daily_final!A10 -> 41699 | B10: =fact_sales_daily_final!E10 -> M01AB | C10: =fact_sales_daily_final!F10 -> 8 | D10: =C10 * VLOOKUP(B10, finance_assumptions!A:B, 2, FALSE) -> 8 | E10: =D10 * 0.75 -> 6 | F10: =D10 - E10 -> 2 | G10: =IF(D10=0, 0, F10/D10) -> 0.25
A11: =fact_sales_daily_final!A11 -> 41699 | B11: =fact_sales_daily_final!E11 -> M01AE | C11: =fact_sales_daily_final!F11 -> 4 | D11: =C11 * VLOOKUP(B11, finance_assumptions!A:B, 2, FALSE) -> 4 | E11: =D11 * 0.75 -> 3 | F11: =D11 - E11 -> 1 | G11: =IF(D11=0, 0, F11/D11) -> 0.25
A12: =fact_sales_daily_final!A12 -> 41699 | B12: =fact_sales_daily_final!E12 -> N02BA | C12: =fact_sales_daily_final!F12 -> 4.4 | D12: =C12 * VLOOKUP(B12, finance_assumptions!A:B, 2, FALSE) -> 4.4 | E12: =D12 * 0.75 -> 3.3 | F12: =D12 - E12 -> 1.1 | G12: =IF(D12=0, 0, F12/D12) -> 0.25
A13: =fact_sales_daily_final!A13 -> 41699 | B13: =fact_sales_daily_final!E13 -> N02BE | C13: =fact_sales_daily_final!F13 -> 50.6 | D13: =C13 * VLOOKUP(B13, finance_assumptions!A:B, 2, FALSE) -> 50.6 | E13: =D13 * 0.75 -> 37.95 | F13: =D13 - E13 -> 12.65 | G13: =IF(D13=0, 0, F13/D13) -> 0.25
... A16849: =fact_sales_daily_final!A16849 -> 43687 | B16849: =fact_sales_daily_final!E16849 -> R06 | C16849: =fact_sales_daily_final!F16849 -> 0 | D16849: =C16849 * VLOOKUP(B16849, finance_assumptions!A:B, 2, FALSE) -> 0 | E16849: =D16849 * 0.75 -> 0 | F16849: =D16849 - E16849 -> 0 | G16849: =IF(D16849=0, 0, F16849/D16849) -> 0

Sheet drug_financial_summary
A1: drug_class | B1: total_revenue | C1: total_profit | D1: avg_margin
A2: M01AB | B2: =SUMIFS(daily_financials!$D:$D, daily_financials!$B:$B, A2) -> 10600.937 | C2: =SUMIFS(daily_financials!$F:$F, daily_financials!$B:$B, A2) -> 2650.2343 | D2: =AVERAGEIFS(daily_financials!$G:$G, daily_financials!$B:$B, A2) -> 0.24525166
A3: M01AE | B3: =SUMIFS(daily_financials!$D:$D, daily_financials!$B:$B, A3) -> 8204.6186 | C3: =SUMIFS(daily_financials!$F:$F, daily_financials!$B:$B, A3) -> 2051.1547 | D3: =AVERAGEIFS(daily_financials!$G:$G, daily_financials!$B:$B, A3) -> 0.2457265
A4: N02BA | B4: =SUMIFS(daily_financials!$D:$D, daily_financials!$B:$B, A4) -> 8172.209 | C4: =SUMIFS(daily_financials!$F:$F, daily_financials!$B:$B, A4) -> 2043.0523 | D4: =AVERAGEIFS(daily_financials!$G:$G, daily_financials!$B:$B, A4) -> 0.24074074
A5: N02BE | B5: =SUMIFS(daily_financials!$D:$D, daily_financials!$B:$B, A5) -> 63005.403 | C5: =SUMIFS(daily_financials!$F:$F, daily_financials!$B:$B, A5) -> 15751.351 | D5: =AVERAGEIFS(daily_financials!$G:$G, daily_financials!$B:$B, A5) -> 0.24691358
A6: N05B | B6: =SUMIFS(daily_financials!$D:$D, daily_financials!$B:$B, A6) -> 18645.737 | C6: =SUMIFS(daily_financials!$F:$F, daily_financials!$B:$B, A6) -> 4661.4344 | D6: =AVERAGEIFS(daily_financials!$G:$G, daily_financials!$B:$B, A6) -> 0.24489554
A7: N05C | B7: =SUMIFS(daily_financials!$D:$D, daily_financials!$B:$B, A7) -> 1249.9583 | C7: =SUMIFS(daily_financials!$F:$F, daily_financials!$B:$B, A7) -> 312.48958 | D7: =AVERAGEIFS(daily_financials!$G:$G, daily_financials!$B:$B, A7) -> 0.080246914
A8: R03 | B8: =SUMIFS(daily_financials!$D:$D, daily_financials!$B:$B, A8) -> 11608.823 | C8: =SUMIFS(daily_financials!$F:$F, daily_financials!$B:$B, A8) -> 2902.2057 | D8: =AVERAGEIFS(daily_financials!$G:$G, daily_financials!$B:$B, A8) -> 0.19254511
A9: R06 | B9: =SUMIFS(daily_financials!$D:$D, daily_financials!$B:$B, A9) -> 6107.8175 | C9: =SUMIFS(daily_financials!$F:$F, daily_financials!$B:$B, A9) -> 1526.9544 | D9: =AVERAGEIFS(daily_financials!$G:$G, daily_financials!$B:$B, A9) -> 0.21961064

Sheet profit_at_risk
A1: drug_class | B1: base_profit | C1: profit_10pct_drop | D1: profit_20pct_drop | E1: loss_10pct | F1: loss_20pct | G1: risk_rank_20pct
A2: M01AB | B2: =drug_financial_summary!C2 -> 2650.2343 | C2: =B2 * 0.9 -> 2385.2108 | D2: =B2 * 0.8 -> 2120.1874 | E2: =B2 - C2 -> 265.02343 | F2: =B2 - D2 -> 530.04685 | G2: =RANK(F2, $F$2:$F$9, 0) -> 4
A3: M01AE | B3: =drug_financial_summary!C3 -> 2051.1547 | C3: =B3 * 0.9 -> 1846.0392 | D3: =B3 * 0.8 -> 1640.9237 | E3: =B3 - C3 -> 205.11547 | F3: =B3 - D3 -> 410.23093 | G3: =RANK(F3, $F$2:$F$9, 0) -> 5
A4: N02BA | B4: =drug_financial_summary!C4 -> 2043.0523 | C4: =B4 * 0.9 -> 1838.747 | D4: =B4 * 0.8 -> 1634.4418 | E4: =B4 - C4 -> 204.30523 | F4: =B4 - D4 -> 408.61045 | G4: =RANK(F4, $F$2:$F$9, 0) -> 6
A5: N02BE | B5: =drug_financial_summary!C5 -> 15751.351 | C5: =B5 * 0.9 -> 14176.216 | D5: =B5 * 0.8 -> 12601.081 | E5: =B5 - C5 -> 1575.1351 | F5: =B5 - D5 -> 3150.2701 | G5: =RANK(F5, $F$2:$F$9, 0) -> 1
A6: N05B | B6: =drug_financial_summary!C6 -> 4661.4344 | C6: =B6 * 0.9 -> 4195.2909 | D6: =B6 * 0.8 -> 3729.1475 | E6: =B6 - C6 -> 466.14344 | F6: =B6 - D6 -> 932.28687 | G6: =RANK(F6, $F$2:$F$9, 0) -> 2
A7: N05C | B7: =drug_financial_summary!C7 -> 312.48958 | C7: =B7 * 0.9 -> 281.24062 | D7: =B7 * 0.8 -> 249.99167 | E7: =B7 - C7 -> 31.248958 | F7: =B7 - D7 -> 62.497917 | G7: =RANK(F7, $F$2:$F$9, 0) -> 8
A8: R03 | B8: =drug_financial_summary!C8 -> 2902.2057 | C8: =B8 * 0.9 -> 2611.9852 | D8: =B8 * 0.8 -> 2321.7646 | E8: =B8 - C8 -> 290.22057 | F8: =B8 - D8 -> 580.44115 | G8: =RANK(F8, $F$2:$F$9, 0) -> 3
A9: R06 | B9: =drug_financial_summary!C9 -> 1526.9544 | C9: =B9 * 0.9 -> 1374.2589 | D9: =B9 * 0.8 -> 1221.5635 | E9: =B9 - C9 -> 152.69544 | F9: =B9 - D9 -> 305.39087 | G9: =RANK(F9, $F$2:$F$9, 0) -> 7

Sheet risk_vs_stability
A1: drug_class | B1: stability_score | C1: loss_20pct | D1: risk_bucket
A2: =profit_at_risk!A2 -> M01AB | B2: =daily_demand_metrics!E2 -> 0.45627718 | C2: =profit_at_risk!F2 -> 530.04685 | D2: =IF(AND(B2<0.3, C2>500), "High Risk / Low Stability", IF(AND(B2>=0.3, C2>500), "High Risk / Stable", IF(AND(B2<0.3, C2<=500), "Low Risk / Low Stability", "Low Risk / Stable"))) -> High Risk / Stable
A3: =profit_at_risk!A3 -> M01AE | B3: =daily_demand_metrics!E3 -> 0.45253518 | C3: =profit_at_risk!F3 -> 410.23093 | D3: =IF(AND(B3<0.3, C3>500), "High Risk / Low Stability", IF(AND(B3>=0.3, C3>500), "High Risk / Stable", IF(AND(B3<0.3, C3<=500), "Low Risk / Low Stability", "Low Risk / Stable"))) -> Low Risk / Stable
A4: =profit_at_risk!A4 -> N02BA | B4: =daily_demand_metrics!E4 -> 0.3857801 | C4: =profit_at_risk!F4 -> 408.61045 | D4: =IF(AND(B4<0.3, C4>500), "High Risk / Low Stability", IF(AND(B4>=0.3, C4>500), "High Risk / Stable", IF(AND(B4<0.3, C4<=500), "Low Risk / Low Stability", "Low Risk / Stable"))) -> Low Risk / Stable
A5: =profit_at_risk!A5 -> N02BE | B5: =daily_demand_metrics!E5 -> 0.47898473 | C5: =profit_at_risk!F5 -> 3150.2701 | D5: =IF(AND(B5<0.3, C5>500), "High Risk / Low Stability", IF(AND(B5>=0.3, C5>500), "High Risk / Stable", IF(AND(B5<0.3, C5<=500), "Low Risk / Low Stability", "Low Risk / Stable"))) -> High Risk / Stable
A6: =profit_at_risk!A6 -> N05B | B6: =daily_demand_metrics!E6 -> 0.36700812 | C6: =profit_at_risk!F6 -> 932.28687 | D6: =IF(AND(B6<0.3, C6>500), "High Risk / Low Stability", IF(AND(B6>=0.3, C6>500), "High Risk / Stable", IF(AND(B6<0.3, C6<=500), "Low Risk / Low Stability", "Low Risk / Stable"))) -> High Risk / Stable
A7: =profit_at_risk!A7 -> N05C | B7: =daily_demand_metrics!E7 -> 0 | C7: =profit_at_risk!F7 -> 62.497917 | D7: =IF(AND(B7<0.3, C7>500), "High Risk / Low Stability", IF(AND(B7>=0.3, C7>500), "High Risk / Stable", IF(AND(B7<0.3, C7<=500), "Low Risk / Low Stability", "Low Risk / Stable"))) -> Low Risk / Low Stability
A8: =profit_at_risk!A8 -> R03 | B8: =daily_demand_metrics!E8 -> 0 | C8: =profit_at_risk!F8 -> 580.44115 | D8: =IF(AND(B8<0.3, C8>500), "High Risk / Low Stability", IF(AND(B8>=0.3, C8>500), "High Risk / Stable", IF(AND(B8<0.3, C8<=500), "Low Risk / Low Stability", "Low Risk / Stable"))) -> High Risk / Low Stability
A9: =profit_at_risk!A9 -> R06 | B9: =daily_demand_metrics!E9 -> 0.16721476 | C9: =profit_at_risk!F9 -> 305.39087 | D9: =IF(AND(B9<0.3, C9>500), "High Risk / Low Stability", IF(AND(B9>=0.3, C9>500), "High Risk / Stable", IF(AND(B9<0.3, C9<=500), "Low Risk / Low Stability", "Low Risk / Stable"))) -> Low Risk / Low Stability
